Workbook
Name articulo: listas!$K$2:$K$6
Name comercial: listas!$I$2:$I$6
Name CONOCIMIENTO: 'tarea uno'!$I$5:$I$6
Name datos: tabladatos2[#All]
Name IINVREAL: SUMAR.SI!$K$4:$K$103
Name INTENCION: 'tarea uno'!$E$5:$E$7
Name Inversión: 'tarea uno'!$H$5:$H$6
Name INVEXP: SUMAR.SI!$J$4:$J$103
Name INVREAL: SUMAR.SI!$J$4:$J$103
Name INVREAL16: SUMAR.SI!$M$4:$M$103
Name INVREAL17: SUMAR.SI!$L$4:$L$103
Name marca: listas!$J$2:$J$6
Name NativeTimeline_FECHA: #N/A
Name SECTOR: SUMAR.SI!$D$4:$D$103
Name SegmentaciónDeDatos_Calificación_Proyectos__1_10: #N/A
Name SegmentaciónDeDatos_COMERCIAL: #N/A
Name SegmentaciónDeDatos_MARCA: #N/A
Name SegmentaciónDeDatos_País_de_orígen: #N/A
Name Trabajo: 'tarea uno'!$G$5:$G$6

Sheet tarea uno
A1: Formato de inscripción
A2: Nombre | B2: Felipe Guzmán
A3: Correo | B3: felipeguzmanbotero@gmail.com | E3: Nivel 1 | G3: Nivel 2
A4: Monto que desea invertir | B4: 10000000 | E4: Intención | G4: Trabajo | H4: Inversión | I4: Conocimiento
A5: Días que se quedará en el país | B5: 2 | E5: Trabajo | G5: Buscando trabajo | H5: Socio de proyecto | I5: Académico
A6: Sector de interés | B6: Tecnología | E6: Inversión | G6: Ofreciendo trabajo | H6: Socio capitalista | I6: Otro tipo
A7: Intención frente a los proyectos | B7: Conocimiento | E7: Conocimiento
A8: Detalle inversión | B8: Otro tipo
A9: Conoce algún proyecto o no | B9: No
A10: País de orígen | B10: Colombia
A12: QUE SE APRENDIO: PARA LAS LISTAS SE LE TIENE QUE PONER EN DATOS, Y DESPUES A VALIDACION PARA PONER EN LISTA Y DESPUES ESPECIFICAR LAS CELDAS. Para hacer LISTAS ENLAZADAS TENEMOS QUE PONERLE EN VALIDACION DE DATOS>LISTAS>Y PONER LA FORMULA =INDIRECTO(LA CELDA DONDE SE COLOCO LA OTRA LISTA), para hacer eso debemos de nombrar el CONJUNTO DE CELDAS como esta en la primer lista para que se relacionen

Sheet UNION Y SEPARACION
B2: UNION | D2: formulas =concatenar y selecconar las celdas =celda&celda
B3: Luis | C3: Silva
B5: =+B3&C3 -> Luis Silva | C5: =CONCATENATE(B3,C3) -> Luis Silva
B6: =B3&" "&C3 -> Luis Silva
B10: SEPARAR | D10: SEPARACION FIJA, ESTA SE LE DA EN DATOS>SEPARACION POR COLUMNA >SEPARACION POR PUNTO FIJO
B11: 0001,Curso Platzi,2018 | D11: 1 | E11: , | F11: Curso Platzi | G11: , | H11: 2018
B12: 0001,Curso Platzi,2018 | D12: 1 | E12: , | F12: Curso Platzi | G12: , | H12: 2018
B13: 0001,Curso Platzi,2018 | D13: 1 | E13: , | F13: Curso Platzi | G13: , | H13: 2018
B14: 0001,Curso Platzi,2018 | D14: 1 | E14: , | F14: Curso Platzi | G14: , | H14: 2018
B15: 0001,Curso Platzi,2018 | D15: 1 | E15: , | F15: Curso Platzi | G15: , | H15: 2018
B18: SEPARAR | D18: SEPARACION DELIMITADA ESTA SE LE DA EN DATOS>SEPARACION POR COLUMNA >SEPARACION DELIMITADA
B19: 1 | C19: Curso Platzi | D19: 2018
B20: 1 | C20: Curso Platzi | D20: 2018
B21: 1 | C21: Curso Platzi | D21: 2018
B22: 1 | C22: Curso Platzi | D22: 2018
B23: 1 | C23: Curso Platzi | D23: 2018
B25: SEPARAR
B26: Nombre | C26: Monto que desea invertir | D26: Días que se quedará en el país | E26: Sector | F26: Intención frente a los proyectos | G26: Detalle inversión | H26: Conoce algún proyecto o no | I26: País de orígen
B27: VALENTINA | C27: 50000000 | D27: 1 | E27: Construcción | F27: Inversión | G27: Socio capitalista | H27: NO | I27: COLOMBIA
B28: GUILLERMO | C28: 10000000 | D28: 1 | E28: Agroindustrial | F28: Inversión | G28: Socio capitalista | H28: NO | I28: COLOMBIA
B29: JOSEP | C29: 0 | D29: 4 | E29: Construcción | F29: Trabajo | G29: Buscando trabajo | H29: NO | I29: COLOMBIA
B30: FERNANDO | C30: 0 | D30: Más de 5 | E30: Tecnología | F30: Trabajo | G30: Buscando trabajo | H30: NO | I30: COLOMBIA
B31: CHRISTIAN | C31: 0 | D31: 1 | E31: Construcción | F31: Trabajo | G31: Ofreciendo trabajo | H31: NO | I31: COLOMBIA
B32: ALBERTO | C32: 0 | D32: 3 | E32: Sector Real | F32: Trabajo | G32: Ofreciendo trabajo | H32: NO | I32: COLOMBIA
B33: NORA | C33: 1000000 | D33: 1 | E33: Sector Real | F33: Inversión | G33: Socio de proyecto | H33: NO | I33: CHILE
B34: MIGUEL | C34: 1000000 | D34: 2 | E34: Tecnología | F34: Inversión | G34: Socio capitalista | H34: SI | I34: COLOMBIA
B35: RAUL | C35: 0 | D35: 2 | E35: Tecnología | F35: Trabajo | G35: Ofreciendo trabajo | H35: SI | I35: BRASIL
B36: ADOLFO | C36: 0 | D36: Más de 5 | E36: Sector Real | F36: Trabajo | G36: Ofreciendo trabajo | H36: NO | I36: COLOMBIA
B37: EDUARDO | C37: 0 | D37: 2 | E37: Tecnología | F37: Trabajo | G37: Buscando trabajo | H37: SI | I37: COLOMBIA
B38: ISAAC | C38: 90000000 | D38: Más de 5 | E38: Tecnología | F38: Inversión | G38: Socio capitalista | H38: NO | I38: COLOMBIA
B39: ANTONIO | C39: 1000000 | D39: 2 | E39: Construcción | F39: Inversión | G39: Socio de proyecto | H39: NO | I39: COLOMBIA
B40: RUBEN | C40: 10000000 | D40: 4 | E40: Tecnología | F40: Inversión | G40: Socio capitalista | H40: SI | I40: COLOMBIA
B41: RICARDO | C41: 10000000 | D41: Más de 5 | E41: Sector Real | F41: Inversión | G41: Socio capitalista | H41: NO | I41: COLOMBIA
B42: FRANCISCO | C42: 1000000 | D42: 1 | E42: Tecnología | F42: Inversión | G42: Socio de proyecto | H42: SI | I42: COLOMBIA
B43: MARTIN | C43: 0 | D43: 2 | E43: Tecnología | F43: Trabajo | G43: Buscando trabajo | H43: SI | I43: COLOMBIA
B44: ANDRÉS | C44: 1000000 | D44: 1 | E44: Tecnología | F44: Inversión | G44: Socio capitalista | H44: NO | I44: COLOMBIA
B45: JUAN PABLO | C45: 1000000 | D45: Más de 5 | E45: Tecnología | F45: Inversión | G45: Socio de proyecto | H45: SI | I45: COLOMBIA
B46: ROBERTO | C46: 10000000 | D46: 1 | E46: Tecnología | F46: Inversión | G46: Socio de proyecto | H46: SI | I46: COLOMBIA
B47: EMILIO | C47: 0 | D47: Más de 5 | E47: Sector Real | F47: Trabajo | G47: Buscando trabajo | H47: NO | I47: COLOMBIA
B48: LEONEL | C48: 20000000 | D48: 2 | E48: Sector Real | F48: Inversión | G48: Socio capitalista | H48: NO | I48: COLOMBIA
...

Sheet SUM PROM Y REDONDEO
A1: Nombre | B1: País de orígen | C1: Sector | D1: Intención frente a los proyectos | E1: Detalle inversión | F1: Conoce algún proyecto o no | G1: Expectativa inversión 2018 | H1: Inversión real 2018 | I1: Inversión real 2017 | J1: Inversión real 2016 | K1: suma manuak | L1: formula | M1: promedio | N1: REDONDEO | O1: SUMAR.SI | P1: =SUM(G3:J101) -> 12768082553 | R1: Rutina de trabajo
A2: ALBERT | B2: COLOMBIA | C2: OTRO | D2: Conocimiento | E2: Académico | F2: NO | G2: 0 | H2: 0 | I2: 96781441 | J2: 47643060 | K2: =H2+I2+J2 -> 144424501 | L2: =SUM(G2:J2) -> 144424501 | M2: =AVERAGE(G2:J2) -> 36106125 | N2: =ROUND(AVERAGE(G2:J2),0) -> 36106125 | O2: =SUMIF(C2:C101,"Tecnología",G2:J101) -> 1069000000 | R2: Sumar la inversión total (manual y fórmula). Sumar al final cada año. Formas de arrastrar.
A3: JOAQUIN | B3: COLOMBIA | C3: Tecnología | D3: Inversión | E3: Socio capitalista | F3: SI | G3: 10000000 | H3: 40848959 | I3: 92963332 | J3: 47565587 | K3: =H3+I3+J3 -> 181377878 | L3: =SUM(G3:J3) -> 191377878 | M3: =AVERAGE(G3:J3) -> 47844470 | N3: =ROUND(AVERAGE(G3:J3),0) -> 47844470 | O3: =SUMIF(C3:C102,"Construcción",G3:J102) -> 211000000 | R3: Operaciones básicas (0 , X, /)
A4: CESAR | B4: COLOMBIA | C4: Construcción | D4: Trabajo | E4: Ofreciendo trabajo | F4: NO | G4: 0 | H4: 0 | I4: 49599457 | J4: 0 | K4: =H4+I4+J4 -> 49599457 | L4: =SUM(G4:J4) -> 49599457 | M4: =AVERAGE(G4:J4) -> 12399864 | N4: =ROUND(AVERAGE(G4:J4),0) -> 12399864 | O4: =SUMIF(C2:C101,"Agroindustrial",G2:J101) -> 50000000 | R4: Sacar promedio de inversión por año (manual y en fórmula)
A5: HUGO | B5: COLOMBIA | C5: Tecnología | D5: Inversión | E5: Socio de proyecto | F5: NO | G5: 10000000 | H5: 78308880 | I5: 3248026 | J5: 27143270 | K5: =H5+I5+J5 -> 108700176 | L5: =SUM(G5:J5) -> 118700176 | M5: =AVERAGE(G5:J5) -> 29675044 | N5: =ROUND(AVERAGE(G5:J5),0) -> 29675044 | R5: Redondear el promedio sin decimales (aparte y después en la fórmula de promedio por año)
A6: VALENTINA | B6: COLOMBIA | C6: Construcción | D6: Inversión | E6: Socio capitalista | F6: NO | G6: 50000000 | H6: 2910571 | I6: 37561085 | J6: 19598007 | K6: =H6+I6+J6 -> 60069663 | L6: =SUM(G6:J6) -> 110069663 | M6: =AVERAGE(G6:J6) -> 27517416 | N6: =ROUND(AVERAGE(G6:J6),0) -> 27517416 | R6: Buscar a ANDRES
A7: GERMAN | B7: COLOMBIA | C7: Tecnología | D7: Inversión | E7: Socio de proyecto | F7: NO | G7: 90000000 | H7: 50075523 | I7: 59142617 | J7: 95314026 | K7: =H7+I7+J7 -> 204532166 | L7: =SUM(G7:J7) -> 294532166 | M7: =AVERAGE(G7:J7) -> 73633042 | N7: =ROUND(AVERAGE(G7:J7),0) -> 73633042 | R7: Reemplazar a ANDRES por Andrés. Remplazar a todos los de construcción por infraestructura.
A8: DAVID | B8: COLOMBIA | C8: Tecnología | D8: Trabajo | E8: Ofreciendo trabajo | F8: NO | G8: 0 | H8: 0 | I8: 0 | J8: 67714973 | K8: =H8+I8+J8 -> 67714973 | L8: =SUM(G8:J8) -> 67714973 | M8: =AVERAGE(G8:J8) -> 16928743 | N8: =ROUND(AVERAGE(G8:J8),0) -> 16928743 | R8: Reto 4 tarea: Encontrar una formula que sume toda la inversión hecha en el sector tecnología en el 2018
A9: MIGUEL | B9: COLOMBIA | C9: Tecnología | D9: Inversión | E9: Socio capitalista | F9: SI | G9: 1000000 | H9: 5305190 | I9: 53291805 | J9: 84809282 | K9: =H9+I9+J9 -> 143406277 | L9: =SUM(G9:J9) -> 144406277 | M9: =AVERAGE(G9:J9) -> 36101569 | N9: =ROUND(AVERAGE(G9:J9),0) -> 36101569
A10: VICENTE | B10: COLOMBIA | C10: Agroindustrial | D10: Trabajo | E10: Ofreciendo trabajo | F10: SI | G10: 0 | H10: 0 | I10: 50085574 | J10: 42495353 | K10: =H10+I10+J10 -> 92580927 | L10: =SUM(G10:J10) -> 92580927 | M10: =AVERAGE(G10:J10) -> 23145232 | N10: =ROUND(AVERAGE(G10:J10),0) -> 23145232 | R10: Fórmulas de texto
A11: ALVARO | B11: COLOMBIA | C11: Sector Real | D11: Inversión | E11: Socio de proyecto | F11: NO | G11: 10000000 | H11: 38941670 | I11: 67846781 | J11: 87726693 | K11: =H11+I11+J11 -> 194515144 | L11: =SUM(G11:J11) -> 204515144 | M11: =AVERAGE(G11:J11) -> 51128786 | N11: =ROUND(AVERAGE(G11:J11),0) -> 51128786 | R11: Bonus 0 fórmulas de texto: mayúscula | S11: =UPPER(R11) -> BONUS 0 FÓRMULAS DE TEXTO: MAYÚSCULA
A12: LUIS | B12: VENEZUELA | C12: Tecnología | D12: Inversión | E12: Socio de proyecto | F12: NO | G12: 1000000 | H12: 28926771 | I12: 56939610 | J12: 92726884 | K12: =H12+I12+J12 -> 178593265 | L12: =SUM(G12:J12) -> 179593265 | M12: =AVERAGE(G12:J12) -> 44898316 | N12: =ROUND(AVERAGE(G12:J12),0) -> 44898316 | R12: Bonus 0 fórmulas de texto: minúscula | S12: =LOWER(R12) -> bonus 0 fórmulas de texto: minúscula
A13: DANIEL | B13: COLOMBIA | C13: Tecnología | D13: Inversión | E13: Socio de proyecto | F13: NO | G13: 1000000 | H13: 34252074 | I13: 0 | J13: 22994819 | K13: =H13+I13+J13 -> 57246893 | L13: =SUM(G13:J13) -> 58246893 | M13: =AVERAGE(G13:J13) -> 14561723 | N13: =ROUND(AVERAGE(G13:J13),0) -> 14561723 | R13: Bonus 0 fórmulas de texto: qué día es hoy | S13: =TODAY() -> 46116
A14: JOSEP | B14: COLOMBIA | C14: Construcción | D14: Trabajo | E14: Buscando trabajo | F14: NO | G14: 0 | H14: 0 | I14: 45347826 | J14: 14301768 | K14: =H14+I14+J14 -> 59649594 | L14: =SUM(G14:J14) -> 59649594 | M14: =AVERAGE(G14:J14) -> 14912398 | N14: =ROUND(AVERAGE(G14:J14),0) -> 14912399
A15: EDUARDO | B15: COLOMBIA | C15: Tecnología | D15: Trabajo | E15: Buscando trabajo | F15: SI | G15: 0 | H15: 0 | I15: 71453938 | J15: 38593802 | K15: =H15+I15+J15 -> 110047740 | L15: =SUM(G15:J15) -> 110047740 | M15: =AVERAGE(G15:J15) -> 27511935 | N15: =ROUND(AVERAGE(G15:J15),0) -> 27511935 | R15: BONUS
A16: LEONEL | B16: COLOMBIA | C16: Sector Real | D16: Inversión | E16: Socio capitalista | F16: NO | G16: 20000000 | H16: 32346156 | I16: 22346275 | J16: 73743047 | K16: =H16+I16+J16 -> 128435478 | L16: =SUM(G16:J16) -> 148435478 | M16: =AVERAGE(G16:J16) -> 37108870 | N16: =ROUND(AVERAGE(G16:J16),0) -> 37108870 | R16: Sumar días a una fecha | S16: 45918 | T16: =TODAY()-S16 -> 198
A17: JORDI | B17: COLOMBIA | C17: Educación | D17: Conocimiento | E17: Académico | F17: NO | G17: 0 | H17: 0 | I17: 96357193 | J17: 67901582 | K17: =H17+I17+J17 -> 164258775 | L17: =SUM(G17:J17) -> 164258775 | M17: =AVERAGE(G17:J17) -> 41064694 | N17: =ROUND(AVERAGE(G17:J17),0) -> 41064694 | R17: Restar fechas
A18: ESTEBAN | B18: COLOMBIA | C18: Tecnología | D18: Inversión | E18: Socio capitalista | F18: NO | G18: 100000000 | H18: 72903049 | I18: 67375493 | J18: 4753995 | K18: =H18+I18+J18 -> 145032537 | L18: =SUM(G18:J18) -> 245032537 | M18: =AVERAGE(G18:J18) -> 61258134 | N18: =ROUND(AVERAGE(G18:J18),0) -> 61258134
A19: JONATHAN | B19: COLOMBIA | C19: Educación | D19: Conocimiento | E19: Académico | F19: NO | G19: 0 | H19: 0 | I19: 80671052 | J19: 58339670 | K19: =H19+I19+J19 -> 139010722 | L19: =SUM(G19:J19) -> 139010722 | M19: =AVERAGE(G19:J19) -> 34752680 | N19: =ROUND(AVERAGE(G19:J19),0) -> 34752681
A20: ANDRES | B20: BRASIL | C20: Sector Real | D20: Trabajo | E20: Buscando trabajo | F20: SI | G20: 0 | H20: 0 | I20: 0 | J20: 44898366 | K20: =H20+I20+J20 -> 44898366 | L20: =SUM(G20:J20) -> 44898366 | M20: =AVERAGE(G20:J20) -> 11224592 | N20: =ROUND(AVERAGE(G20:J20),0) -> 11224592
A21: JOSE | B21: COLOMBIA | C21: Tecnología | D21: Inversión | E21: Socio de proyecto | F21: NO | G21: 1000000 | H21: 96696256 | I21: 62106884 | J21: 85228190 | K21: =H21+I21+J21 -> 244031330 | L21: =SUM(G21:J21) -> 245031330 | M21: =AVERAGE(G21:J21) -> 61257832 | N21: =ROUND(AVERAGE(G21:J21),0) -> 61257833
A22: FELIX | B22: COLOMBIA | C22: Tecnología | D22: Inversión | E22: Socio de proyecto | F22: NO | G22: 10000000 | H22: 51531809 | I22: 99819688 | J22: 24233431 | K22: =H22+I22+J22 -> 175584928 | L22: =SUM(G22:J22) -> 185584928 | M22: =AVERAGE(G22:J22) -> 46396232 | N22: =ROUND(AVERAGE(G22:J22),0) -> 46396232
A23: PABLO | B23: COLOMBIA | C23: Agroindustrial | D23: Inversión | E23: Socio capitalista | F23: SI | G23: 0 | H23: 0 | I23: 34214902 | J23: 24896611 | K23: =H23+I23+J23 -> 59111513 | L23: =SUM(G23:J23) -> 59111513 | M23: =AVERAGE(G23:J23) -> 14777878 | N23: =ROUND(AVERAGE(G23:J23),0) -> 14777878
A24: MANUEL | B24: ARGENTINA | C24: Sector Real | D24: Trabajo | E24: Ofreciendo trabajo | F24: NO | G24: 0 | H24: 0 | I24: 7121108 | J24: 6991703 | K24: =H24+I24+J24 -> 14112811 | L24: =SUM(G24:J24) -> 14112811 | M24: =AVERAGE(G24:J24) -> 3528202.8 | N24: =ROUND(AVERAGE(G24:J24),0) -> 3528203
A25: LORENZO | B25: COLOMBIA | C25: Agroindustrial | D25: Inversión | E25: Socio capitalista | F25: NO | G25: 20000000 | H25: 93037614 | I25: 48185946 | J25: 75039300 | K25: =H25+I25+J25 -> 216262860 | L25: =SUM(G25:J25) -> 236262860 | M25: =AVERAGE(G25:J25) -> 59065715 | N25: =ROUND(AVERAGE(G25:J25),0) -> 59065715
A26: ISAAC | B26: COLOMBIA | C26: Tecnología | D26: Inversión | E26: Socio capitalista | F26: NO | G26: 90000000 | H26: 62088180 | I26: 18047519 | J26: 3738158 | K26: =H26+I26+J26 -> 83873857 | L26: =SUM(G26:J26) -> 173873857 | M26: =AVERAGE(G26:J26) -> 43468464 | N26: =ROUND(AVERAGE(G26:J26),0) -> 43468464
A27: MARIA | B27: COLOMBIA | C27: Sector Real | D27: Inversión | E27: Socio capitalista | F27: NO | G27: 1000000 | H27: 1160848 | I27: 32268145 | J27: 13339687 | K27: =H27+I27+J27 -> 46768680 | L27: =SUM(G27:J27) -> 47768680 | M27: =AVERAGE(G27:J27) -> 11942170 | N27: =ROUND(AVERAGE(G27:J27),0) -> 11942170
A28: ANGEL | B28: COLOMBIA | C28: Tecnología | D28: Trabajo | E28: Ofreciendo trabajo | F28: NO | G28: 0 | H28: 0 | I28: 21224611 | J28: 62562457 | K28: =H28+I28+J28 -> 83787068 | L28: =SUM(G28:J28) -> 83787068 | M28: =AVERAGE(G28:J28) -> 20946767 | N28: =ROUND(AVERAGE(G28:J28),0) -> 20946767
A29: ADOLFO | B29: COLOMBIA | C29: Sector Real | D29: Trabajo | E29: Ofreciendo trabajo | F29: NO | G29: 0 | H29: 0 | I29: 85434615 | J29: 79508333 | K29: =H29+I29+J29 -> 164942948 | L29: =SUM(G29:J29) -> 164942948 | M29: =AVERAGE(G29:J29) -> 41235737 | N29: =ROUND(AVERAGE(G29:J29),0) -> 41235737
... A101: ADRIAN | B101: COLOMBIA | C101: Tecnología | D101: Trabajo | E101: Ofreciendo trabajo | F101: NO | G101: 0 | H101: 0 | I101: 24965127 | J101: 41129782 | K101: =H101+I101+J101 -> 66094909 | L101: =SUM(G101:J101) -> 66094909 | M101: =AVERAGE(G101:J101) -> 16523727 | N101: =ROUND(AVERAGE(G101:J101),0) -> 16523727

Sheet SUMAR.SI
Q1: Reto clase anterior: Encontrar una formula que sume toda la inversión hecha en el sector tecnología en el 2018
B3: Nombre | C3: País de orígen | D3: Sector | E3: Intención frente a los proyectos | F3: Detalle inversión | G3: Conoce algún proyecto o no | H3: Calificación Feria (1010) | I3: Calificación Proyectos (1010) | J3: Expectativa inversión 2018 | K3: Inversión real 2018 | L3: Inversión real 2017 | M3: Inversión real 2016 | N3: var 201702016 | O3: VAR 201702018 | Q3: ¿Cuál es la inversión real 2018 de cada sector? | R3: Columna1 | S3: =sumar.si(RANGO DE DATOS, EL DATO O TEXTO, RANGO A SUMAR) | U3: ¿Cuál es la DIFERENCIA ENTRE inversión real Y EXPECTATIVA 2018 de cada sector? | V3: Columna1
B4: ALBERT | C4: COLOMBIA | D4: Educación | E4: Conocimiento | F4: Académico | G4: NO | H4: 3 | I4: 8 | J4: 0 | K4: 0 | L4: 96781441 | M4: 47643060 | N4: =(Tabla3[[#This Row],[Inversión real 2017]]-Tabla3[[#This Row],[Inversión real 2016]])/Tabla3[[#This Row],[Inversión real 2016]] -> 1.0313859 | O4: =(Tabla3[[#This Row],[Inversión real 2017]]-Tabla3[[#This Row],[Inversión real 2018]])/Tabla3[[#This Row],[Inversión real 2018]] -> #DIV/0! | Q4: Sector | R4: Inversión 2018 | U4: Sector | V4: Inversión 2018
B5: JOAQUIN | C5: COLOMBIA | D5: Tecnología | E5: Inversión | F5: Socio capitalista | G5: SI | H5: 8 | I5: 7 | J5: 10000000 | K5: 40848959 | L5: 92963332 | M5: 47565587 | N5: =(Tabla3[[#This Row],[Inversión real 2017]]-Tabla3[[#This Row],[Inversión real 2016]])/Tabla3[[#This Row],[Inversión real 2016]] -> 0.95442415 | O5: =(Tabla3[[#This Row],[Inversión real 2017]]-Tabla3[[#This Row],[Inversión real 2018]])/Tabla3[[#This Row],[Inversión real 2018]] -> 1.2757822 | Q5: Tecnología | R5: 2002341114 | S5: =SUMIF($D$4:$D$103,Q5,$K$4:$K$103) -> 2002341114 | U5: Tecnología | V5: =SUMIF($D$4:$D$103,U5,$K$4:$K$103)-SUMIF($D$4:$D$103,U5,$J$4:$J$103) -> 933341114
B6: CESAR | C6: COLOMBIA | D6: Construcción | E6: Trabajo | F6: Ofreciendo trabajo | G6: NO | H6: 5 | I6: 10 | J6: $ - | K6: $ - | L6: 49599457 | M6: $ - | N6: =(Tabla3[[#This Row],[Inversión real 2017]]-Tabla3[[#This Row],[Inversión real 2016]])/Tabla3[[#This Row],[Inversión real 2016]] -> #VALUE! | O6: =(Tabla3[[#This Row],[Inversión real 2017]]-Tabla3[[#This Row],[Inversión real 2018]])/Tabla3[[#This Row],[Inversión real 2018]] -> #VALUE! | Q6: Sector Real | R6: 535791961 | S6: =SUMIF($D$4:$D$103,Q6,$K$4:$K$103) -> 535791961 | U6: Sector Real | V6: =SUMIF($D$4:$D$103,U6,$K$4:$K$103)-SUMIF($D$4:$D$103,U6,$J$4:$J$103) -> 298791961
B7: HUGO | C7: COLOMBIA | D7: Tecnología | E7: Inversión | F7: Socio de proyecto | G7: NO | H7: 4 | I7: 8 | J7: 10000000 | K7: 78308880 | L7: 3248026 | M7: 27143270 | N7: =(Tabla3[[#This Row],[Inversión real 2017]]-Tabla3[[#This Row],[Inversión real 2016]])/Tabla3[[#This Row],[Inversión real 2016]] -> -0.8803377 | O7: =(Tabla3[[#This Row],[Inversión real 2017]]-Tabla3[[#This Row],[Inversión real 2018]])/Tabla3[[#This Row],[Inversión real 2018]] -> -0.95852289 | Q7: Agroindustrial | R7: 253232607 | S7: =SUMIF($D$4:$D$103,Q7,$K$4:$K$103) -> 253232607 | U7: Agroindustrial | V7: =SUMIF($D$4:$D$103,U7,$K$4:$K$103)-SUMIF($D$4:$D$103,U7,$J$4:$J$103) -> 203232607
B8: VALENTINA | C8: COLOMBIA | D8: Construcción | E8: Inversión | F8: Socio capitalista | G8: NO | H8: 4 | I8: 9 | J8: 50000000 | K8: 2910571 | L8: 37561085 | M8: 19598007 | N8: =(Tabla3[[#This Row],[Inversión real 2017]]-Tabla3[[#This Row],[Inversión real 2016]])/Tabla3[[#This Row],[Inversión real 2016]] -> 0.91657677 | O8: =(Tabla3[[#This Row],[Inversión real 2017]]-Tabla3[[#This Row],[Inversión real 2018]])/Tabla3[[#This Row],[Inversión real 2018]] -> 11.905057 | Q8: Construcción | R8: 187304900 | S8: =SUMIF($D$4:$D$103,Q8,$K$4:$K$103) -> 187304900 | U8: Construcción | V8: =SUMIF($D$4:$D$103,U8,$K$4:$K$103)-SUMIF($D$4:$D$103,U8,$J$4:$J$103) -> -23695100
B9: GERMAN | C9: COLOMBIA | D9: Tecnología | E9: Inversión | F9: Socio de proyecto | G9: NO | H9: 9 | I9: 7 | J9: 90000000 | K9: 50075523 | L9: 59142617 | M9: 95314026 | N9: =(Tabla3[[#This Row],[Inversión real 2017]]-Tabla3[[#This Row],[Inversión real 2016]])/Tabla3[[#This Row],[Inversión real 2016]] -> -0.37949723 | O9: =(Tabla3[[#This Row],[Inversión real 2017]]-Tabla3[[#This Row],[Inversión real 2018]])/Tabla3[[#This Row],[Inversión real 2018]] -> 0.18106838 | Q9: Educación | R9: $ - | S9: =SUMIF($D$4:$D$103,Q9,$K$4:$K$103) -> 0 | U9: Educación | V9: =SUMIF($D$4:$D$103,U9,$K$4:$K$103)-SUMIF($D$4:$D$103,U9,$J$4:$J$103) -> 0
B10: DAVID | C10: COLOMBIA | D10: Tecnología | E10: Trabajo | F10: Ofreciendo trabajo | G10: NO | H10: 5 | I10: 9 | J10: $ - | K10: $ - | L10: $ - | M10: 67714973 | N10: =(Tabla3[[#This Row],[Inversión real 2017]]-Tabla3[[#This Row],[Inversión real 2016]])/Tabla3[[#This Row],[Inversión real 2016]] -> #VALUE! | O10: =(Tabla3[[#This Row],[Inversión real 2017]]-Tabla3[[#This Row],[Inversión real 2018]])/Tabla3[[#This Row],[Inversión real 2018]] -> #VALUE!
B11: MIGUEL | C11: COLOMBIA | D11: Tecnología | E11: Inversión | F11: Socio capitalista | G11: SI | H11: 8 | I11: 10 | J11: 1000000 | K11: 5305190 | L11: 53291805 | M11: 84809282 | N11: =(Tabla3[[#This Row],[Inversión real 2017]]-Tabla3[[#This Row],[Inversión real 2016]])/Tabla3[[#This Row],[Inversión real 2016]] -> -0.37162768 | O11: =(Tabla3[[#This Row],[Inversión real 2017]]-Tabla3[[#This Row],[Inversión real 2018]])/Tabla3[[#This Row],[Inversión real 2018]] -> 9.0452208
B12: VICENTE | C12: COLOMBIA | D12: Agroindustrial | E12: Trabajo | F12: Ofreciendo trabajo | G12: SI | H12: 8 | I12: 3 | J12: $ - | K12: $ - | L12: 50085574 | M12: 42495353 | N12: =(Tabla3[[#This Row],[Inversión real 2017]]-Tabla3[[#This Row],[Inversión real 2016]])/Tabla3[[#This Row],[Inversión real 2016]] -> 0.17861297 | O12: =(Tabla3[[#This Row],[Inversión real 2017]]-Tabla3[[#This Row],[Inversión real 2018]])/Tabla3[[#This Row],[Inversión real 2018]] -> #VALUE! | Q12: ¿Cuántas personas vienen en las diferentes modalidades? ¿Porcentaje de cada uno? | T12: contar.si | U12: ¿Cuál es la DIFERENCIA ENTRE inversión del 2017 y 2016? | V12: Columna1
B13: ALVARO | C13: COLOMBIA | D13: Sector Real | E13: Inversión | F13: Socio de proyecto | G13: NO | H13: 5 | I13: 9 | J13: 10000000 | K13: 38941670 | L13: 67846781 | M13: 87726693 | N13: =(Tabla3[[#This Row],[Inversión real 2017]]-Tabla3[[#This Row],[Inversión real 2016]])/Tabla3[[#This Row],[Inversión real 2016]] -> -0.22661189 | O13: =(Tabla3[[#This Row],[Inversión real 2017]]-Tabla3[[#This Row],[Inversión real 2018]])/Tabla3[[#This Row],[Inversión real 2018]] -> 0.74226686 | Q13: Intención | R13: Cantidad | S13: Porcentaje | U13: Sector | V13: Inversión 2018
B14: LUIS | C14: VENEZUELA | D14: Tecnología | E14: Inversión | F14: Socio de proyecto | G14: NO | H14: 4 | I14: 5 | J14: 1000000 | K14: 28926771 | L14: 56939610 | M14: 92726884 | N14: =(Tabla3[[#This Row],[Inversión real 2017]]-Tabla3[[#This Row],[Inversión real 2016]])/Tabla3[[#This Row],[Inversión real 2016]] -> -0.38594281 | O14: =(Tabla3[[#This Row],[Inversión real 2017]]-Tabla3[[#This Row],[Inversión real 2018]])/Tabla3[[#This Row],[Inversión real 2018]] -> 0.96840532 | Q14: Trabajo | R14: =ROUND(COUNTIF($E$4:$E$103,Q14),0) -> 33 | S14: =R14/SUM($R$14:$R$16) -> 0.33 | U14: Tecnología | V14: =SUMIF($D$4:$D$103,U14,$L$4:$L$103)-SUMIF($D$4:$D$103,U14,$M$4:$M$103) -> -497331542
B15: DANIEL | C15: COLOMBIA | D15: Tecnología | E15: Inversión | F15: Socio de proyecto | G15: NO | H15: 3 | I15: 8 | J15: 1000000 | K15: 34252074 | L15: $ - | M15: 22994819 | N15: =(Tabla3[[#This Row],[Inversión real 2017]]-Tabla3[[#This Row],[Inversión real 2016]])/Tabla3[[#This Row],[Inversión real 2016]] -> #VALUE! | O15: =(Tabla3[[#This Row],[Inversión real 2017]]-Tabla3[[#This Row],[Inversión real 2018]])/Tabla3[[#This Row],[Inversión real 2018]] -> #VALUE! | Q15: Inversión | R15: =ROUND(COUNTIF($E$4:$E$103,Q15),0) -> 59 | S15: =R15/SUM($R$14:$R$16) -> 0.59 | U15: Sector Real | V15: =SUMIF($D$4:$D$103,U15,$L$4:$L$103)-SUMIF($D$4:$D$103,U15,$M$4:$M$103) -> 1143341
B16: JOSEP | C16: COLOMBIA | D16: Construcción | E16: Trabajo | F16: Buscando trabajo | G16: NO | H16: 7 | I16: 9 | J16: $ - | K16: $ - | L16: 45347826 | M16: 14301768 | N16: =(Tabla3[[#This Row],[Inversión real 2017]]-Tabla3[[#This Row],[Inversión real 2016]])/Tabla3[[#This Row],[Inversión real 2016]] -> 2.1707846 | O16: =(Tabla3[[#This Row],[Inversión real 2017]]-Tabla3[[#This Row],[Inversión real 2018]])/Tabla3[[#This Row],[Inversión real 2018]] -> #VALUE! | Q16: Conocimiento | R16: =ROUND(COUNTIF($E$4:$E$103,Q16),0) -> 8 | S16: =R16/SUM($R$14:$R$16) -> 0.08 | U16: Agroindustrial | V16: =SUMIF($D$4:$D$103,U16,$L$4:$L$103)-SUMIF($D$4:$D$103,U16,$M$4:$M$103) -> 129879240
B17: EDUARDO | C17: COLOMBIA | D17: Tecnología | E17: Trabajo | F17: Buscando trabajo | G17: SI | H17: 4 | I17: 8 | J17: $ - | K17: $ - | L17: 71453938 | M17: 38593802 | N17: =(Tabla3[[#This Row],[Inversión real 2017]]-Tabla3[[#This Row],[Inversión real 2016]])/Tabla3[[#This Row],[Inversión real 2016]] -> 0.85143558 | O17: =(Tabla3[[#This Row],[Inversión real 2017]]-Tabla3[[#This Row],[Inversión real 2018]])/Tabla3[[#This Row],[Inversión real 2018]] -> #VALUE! | U17: Construcción | V17: =SUMIF($D$4:$D$103,U17,$L$4:$L$103)-SUMIF($D$4:$D$103,U17,$M$4:$M$103) -> 20785398
B18: LEONEL | C18: COLOMBIA | D18: Sector Real | E18: Inversión | F18: Socio capitalista | G18: NO | H18: 9 | I18: 10 | J18: 20000000 | K18: 32346156 | L18: 22346275 | M18: 73743047 | N18: =(Tabla3[[#This Row],[Inversión real 2017]]-Tabla3[[#This Row],[Inversión real 2016]])/Tabla3[[#This Row],[Inversión real 2016]] -> -0.69697109 | O18: =(Tabla3[[#This Row],[Inversión real 2017]]-Tabla3[[#This Row],[Inversión real 2018]])/Tabla3[[#This Row],[Inversión real 2018]] -> -0.30915207 | U18: Educación | V18: =SUMIF($D$4:$D$103,U18,$L$4:$L$103)-SUMIF($D$4:$D$103,U18,$M$4:$M$103) -> 256825755
B19: JORDI | C19: COLOMBIA | D19: Educación | E19: Conocimiento | F19: Académico | G19: NO | H19: 4 | I19: 6 | J19: $ - | K19: $ - | L19: 96357193 | M19: 67901582 | N19: =(Tabla3[[#This Row],[Inversión real 2017]]-Tabla3[[#This Row],[Inversión real 2016]])/Tabla3[[#This Row],[Inversión real 2016]] -> 0.4190714 | O19: =(Tabla3[[#This Row],[Inversión real 2017]]-Tabla3[[#This Row],[Inversión real 2018]])/Tabla3[[#This Row],[Inversión real 2018]] -> #VALUE! | Q19: Otras fórmulas | T19: sólo explicar
B20: ESTEBAN | C20: COLOMBIA | D20: Tecnología | E20: Inversión | F20: Socio capitalista | G20: NO | H20: 5 | I20: 7 | J20: 100000000 | K20: 72903049 | L20: 67375493 | M20: 4753995 | N20: =(Tabla3[[#This Row],[Inversión real 2017]]-Tabla3[[#This Row],[Inversión real 2016]])/Tabla3[[#This Row],[Inversión real 2016]] -> 13.172395 | O20: =(Tabla3[[#This Row],[Inversión real 2017]]-Tabla3[[#This Row],[Inversión real 2018]])/Tabla3[[#This Row],[Inversión real 2018]] -> -0.075820642 | Q20: Contar | R20: Cuenta el número de celdas que contienen números en un rango determinado | T20: =COUNT(F4:H11) -> 8 | U20: ¿Cuál es la DIFERENCIA ENTRE inversión del 2017 y 2016? | V20: Columna1
B21: JONATHAN | C21: COLOMBIA | D21: Educación | E21: Conocimiento | F21: Académico | G21: NO | H21: 6 | I21: 7 | J21: $ - | K21: $ - | L21: 80671052 | M21: 58339670 | N21: =(Tabla3[[#This Row],[Inversión real 2017]]-Tabla3[[#This Row],[Inversión real 2016]])/Tabla3[[#This Row],[Inversión real 2016]] -> 0.38278211 | O21: =(Tabla3[[#This Row],[Inversión real 2017]]-Tabla3[[#This Row],[Inversión real 2018]])/Tabla3[[#This Row],[Inversión real 2018]] -> #VALUE! | U21: Sector | V21: Inversión 2018
B22: FELIPE | C22: BRASIL | D22: Sector Real | E22: Trabajo | F22: Buscando trabajo | G22: SI | H22: 9 | I22: 8 | J22: $ - | K22: $ - | L22: $ - | M22: 44898366 | N22: =(Tabla3[[#This Row],[Inversión real 2017]]-Tabla3[[#This Row],[Inversión real 2016]])/Tabla3[[#This Row],[Inversión real 2016]] -> #VALUE! | O22: =(Tabla3[[#This Row],[Inversión real 2017]]-Tabla3[[#This Row],[Inversión real 2018]])/Tabla3[[#This Row],[Inversión real 2018]] -> #VALUE! | Q22: ContarA | R22: Cuenta el número de celdas no vacías en un rango determinado | T22: =COUNTA(F4:H11) -> 24 | U22: Tecnología | V22: =SUMIF(SECTOR,U22,IINVREAL) -> 2002341114
B23: JOSE | C23: COLOMBIA | D23: Tecnología | E23: Inversión | F23: Socio de proyecto | G23: NO | H23: 5 | I23: 6 | J23: 1000000 | K23: 96696256 | L23: 62106884 | M23: 85228190 | N23: =(Tabla3[[#This Row],[Inversión real 2017]]-Tabla3[[#This Row],[Inversión real 2016]])/Tabla3[[#This Row],[Inversión real 2016]] -> -0.27128707 | O23: =(Tabla3[[#This Row],[Inversión real 2017]]-Tabla3[[#This Row],[Inversión real 2018]])/Tabla3[[#This Row],[Inversión real 2018]] -> -0.3577116 | U23: Sector Real | V23: =SUMIF(SECTOR,U23,IINVREAL) -> 535791961
B24: FELIX | C24: COLOMBIA | D24: Tecnología | E24: Inversión | F24: Socio de proyecto | G24: NO | H24: 6 | I24: 7 | J24: 10000000 | K24: 51531809 | L24: 99819688 | M24: 24233431 | N24: =(Tabla3[[#This Row],[Inversión real 2017]]-Tabla3[[#This Row],[Inversión real 2016]])/Tabla3[[#This Row],[Inversión real 2016]] -> 3.1190902 | O24: =(Tabla3[[#This Row],[Inversión real 2017]]-Tabla3[[#This Row],[Inversión real 2018]])/Tabla3[[#This Row],[Inversión real 2018]] -> 0.93704995 | Q24: Pregunta: ¿En qué escenarios pueden ser útiles estas fórmulas? | U24: Agroindustrial | V24: =SUMIF(SECTOR,U24,IINVREAL) -> 253232607
B25: PABLO | C25: COLOMBIA | D25: Agroindustrial | E25: Inversión | F25: Socio capitalista | G25: SI | H25: 6 | I25: 10 | J25: $ - | K25: $ - | L25: 34214902 | M25: 24896611 | N25: =(Tabla3[[#This Row],[Inversión real 2017]]-Tabla3[[#This Row],[Inversión real 2016]])/Tabla3[[#This Row],[Inversión real 2016]] -> 0.3742795 | O25: =(Tabla3[[#This Row],[Inversión real 2017]]-Tabla3[[#This Row],[Inversión real 2018]])/Tabla3[[#This Row],[Inversión real 2018]] -> #VALUE! | U25: Construcción | V25: =SUMIF(SECTOR,U25,IINVREAL) -> 187304900
B26: MANUEL | C26: ARGENTINA | D26: Sector Real | E26: Trabajo | F26: Ofreciendo trabajo | G26: NO | H26: 8 | I26: 5 | J26: $ - | K26: $ - | L26: 7121108 | M26: 6991703 | N26: =(Tabla3[[#This Row],[Inversión real 2017]]-Tabla3[[#This Row],[Inversión real 2016]])/Tabla3[[#This Row],[Inversión real 2016]] -> 0.018508366 | O26: =(Tabla3[[#This Row],[Inversión real 2017]]-Tabla3[[#This Row],[Inversión real 2018]])/Tabla3[[#This Row],[Inversión real 2018]] -> #VALUE! | U26: Educación | V26: =SUMIF(SECTOR,U26,IINVREAL) -> 0
B27: LORENZO | C27: COLOMBIA | D27: Agroindustrial | E27: Inversión | F27: Socio capitalista | G27: NO | H27: 7 | I27: 10 | J27: 20000000 | K27: 93037614 | L27: 48185946 | M27: 75039300 | N27: =(Tabla3[[#This Row],[Inversión real 2017]]-Tabla3[[#This Row],[Inversión real 2016]])/Tabla3[[#This Row],[Inversión real 2016]] -> -0.3578572 | O27: =(Tabla3[[#This Row],[Inversión real 2017]]-Tabla3[[#This Row],[Inversión real 2018]])/Tabla3[[#This Row],[Inversión real 2018]] -> -0.48208102 | Q27: ¿Cuál es la calificación promedio? | S27: promedio sencillo
B28: ISAAC | C28: COLOMBIA | D28: Tecnología | E28: Inversión | F28: Socio capitalista | G28: NO | H28: 9 | I28: 10 | J28: 90000000 | K28: 62088180 | L28: 18047519 | M28: 3738158 | N28: =(Tabla3[[#This Row],[Inversión real 2017]]-Tabla3[[#This Row],[Inversión real 2016]])/Tabla3[[#This Row],[Inversión real 2016]] -> 3.8279177 | O28: =(Tabla3[[#This Row],[Inversión real 2017]]-Tabla3[[#This Row],[Inversión real 2018]])/Tabla3[[#This Row],[Inversión real 2018]] -> -0.7093244 | Q28: Tipo | R28: Calificación | U28: VARIACION PORCENTUAL TOTAL 2016-2017
B29: MARIA | C29: COLOMBIA | D29: Sector Real | E29: Inversión | F29: Socio capitalista | G29: NO | H29: 3 | I29: 9 | J29: 1000000 | K29: 1160848 | L29: 32268145 | M29: 13339687 | N29: =(Tabla3[[#This Row],[Inversión real 2017]]-Tabla3[[#This Row],[Inversión real 2016]])/Tabla3[[#This Row],[Inversión real 2016]] -> 1.4189582 | O29: =(Tabla3[[#This Row],[Inversión real 2017]]-Tabla3[[#This Row],[Inversión real 2018]])/Tabla3[[#This Row],[Inversión real 2018]] -> 26.797046 | Q29: Feria | R29: =AVERAGE(H4:H103) -> 5.81 | U29: =(SUM(INVREAL17)-SUM(INVREAL16))/SUM(INVREAL16) -> -0.020979823 | V29: VARIANZA
B30: ANGEL | C30: COLOMBIA | D30: Tecnología | E30: Trabajo | F30: Ofreciendo trabajo | G30: NO | H30: 6 | I30: 2 | J30: $ - | K30: $ - | L30: 21224611 | M30: 62562457 | N30: =(Tabla3[[#This Row],[Inversión real 2017]]-Tabla3[[#This Row],[Inversión real 2016]])/Tabla3[[#This Row],[Inversión real 2016]] -> -0.66074525 | O30: =(Tabla3[[#This Row],[Inversión real 2017]]-Tabla3[[#This Row],[Inversión real 2018]])/Tabla3[[#This Row],[Inversión real 2018]] -> #VALUE! | Q30: Proyectos | R30: =AVERAGE(I4:I103) -> 7.56
B31: ADOLFO | C31: COLOMBIA | D31: Sector Real | E31: Trabajo | F31: Ofreciendo trabajo | G31: NO | H31: 9 | I31: 9 | J31: $ - | K31: $ - | L31: 85434615 | M31: 79508333 | N31: =(Tabla3[[#This Row],[Inversión real 2017]]-Tabla3[[#This Row],[Inversión real 2016]])/Tabla3[[#This Row],[Inversión real 2016]] -> 0.074536615 | O31: =(Tabla3[[#This Row],[Inversión real 2017]]-Tabla3[[#This Row],[Inversión real 2018]])/Tabla3[[#This Row],[Inversión real 2018]] -> #VALUE! | Q31: Agregado | R31: =AVERAGE(R29:R30) -> 6.685 | S31: promedio sencillo
B32: ERNESTO | C32: COLOMBIA | D32: Tecnología | E32: Inversión | F32: Socio de proyecto | G32: NO | H32: 8 | I32: 7 | J32: 90000000 | K32: 23888885 | L32: 68725539 | M32: 78613526 | N32: =(Tabla3[[#This Row],[Inversión real 2017]]-Tabla3[[#This Row],[Inversión real 2016]])/Tabla3[[#This Row],[Inversión real 2016]] -> -0.12577972 | O32: =(Tabla3[[#This Row],[Inversión real 2017]]-Tabla3[[#This Row],[Inversión real 2018]])/Tabla3[[#This Row],[Inversión real 2018]] -> 1.8768835
B33: RAFAEL | C33: COLOMBIA | D33: Sector Real | E33: Inversión | F33: Socio capitalista | G33: SI | H33: 8 | I33: 8 | J33: 10000000 | K33: 23464528 | L33: 904543 | M33: $ - | N33: =(Tabla3[[#This Row],[Inversión real 2017]]-Tabla3[[#This Row],[Inversión real 2016]])/Tabla3[[#This Row],[Inversión real 2016]] -> #VALUE! | O33: =(Tabla3[[#This Row],[Inversión real 2017]]-Tabla3[[#This Row],[Inversión real 2018]])/Tabla3[[#This Row],[Inversión real 2018]] -> -0.96145062 | Q33: ¿Cuál es la calificación promedio de los proyectos de acuerdo a cada uno de los sectores? | S33: promedio.si
B34: TOMAS | C34: COLOMBIA | D34: Agroindustrial | E34: Trabajo | F34: Ofreciendo trabajo | G34: NO | H34: 6 | I34: 8 | J34: $ - | K34: $ - | L34: 66204884 | M34: 27801447 | N34: =(Tabla3[[#This Row],[Inversión real 2017]]-Tabla3[[#This Row],[Inversión real 2016]])/Tabla3[[#This Row],[Inversión real 2016]] -> 1.3813467 | O34: =(Tabla3[[#This Row],[Inversión real 2017]]-Tabla3[[#This Row],[Inversión real 2018]])/Tabla3[[#This Row],[Inversión real 2018]] -> #VALUE! | Q34: Sector | R34: Calificación
B35: MARCOS | C35: BRASIL | D35: Sector Real | E35: Trabajo | F35: Buscando trabajo | G35: SI | H35: 3 | I35: 5 | J35: $ - | K35: $ - | L35: 30987169 | M35: 7339680 | N35: =(Tabla3[[#This Row],[Inversión real 2017]]-Tabla3[[#This Row],[Inversión real 2016]])/Tabla3[[#This Row],[Inversión real 2016]] -> 3.2218692 | O35: =(Tabla3[[#This Row],[Inversión real 2017]]-Tabla3[[#This Row],[Inversión real 2018]])/Tabla3[[#This Row],[Inversión real 2018]] -> #VALUE! | Q35: Tecnología | R35: =AVERAGEIF($D$4:$D$103,Q35,$I$4:$I$103) -> 7.3333333
B36: MARIO | C36: COLOMBIA | D36: Tecnología | E36: Inversión | F36: Socio capitalista | G36: NO | H36: 6 | I36: 7 | J36: 10000000 | K36: 22390348 | L36: 24476166 | M36: $ - | N36: =(Tabla3[[#This Row],[Inversión real 2017]]-Tabla3[[#This Row],[Inversión real 2016]])/Tabla3[[#This Row],[Inversión real 2016]] -> #VALUE! | O36: =(Tabla3[[#This Row],[Inversión real 2017]]-Tabla3[[#This Row],[Inversión real 2018]])/Tabla3[[#This Row],[Inversión real 2018]] -> 0.093157016 | Q36: Sector Real | R36: =AVERAGEIF($D$4:$D$103,Q36,$I$4:$I$103) -> 8.0952381
B37: ARTURO | C37: COLOMBIA | D37: Sector Real | E37: Inversión | F37: Socio de proyecto | G37: NO | H37: 6 | I37: 10 | J37: 20000000 | K37: 31670482 | L37: 15619630 | M37: 59838390 | N37: =(Tabla3[[#This Row],[Inversión real 2017]]-Tabla3[[#This Row],[Inversión real 2016]])/Tabla3[[#This Row],[Inversión real 2016]] -> -0.73896975 | O37: =(Tabla3[[#This Row],[Inversión real 2017]]-Tabla3[[#This Row],[Inversión real 2018]])/Tabla3[[#This Row],[Inversión real 2018]] -> -0.50680795 | Q37: Agroindustrial | R37: =AVERAGEIF($D$4:$D$103,Q37,$I$4:$I$103) -> 7
B38: EUGENIO | C38: COLOMBIA | D38: Construcción | E38: Inversión | F38: Socio de proyecto | G38: NO | H38: 8 | I38: 5 | J38: 20000000 | K38: 81056910 | L38: 96438403 | M38: 90723423 | N38: =(Tabla3[[#This Row],[Inversión real 2017]]-Tabla3[[#This Row],[Inversión real 2016]])/Tabla3[[#This Row],[Inversión real 2016]] -> 0.062993434 | O38: =(Tabla3[[#This Row],[Inversión real 2017]]-Tabla3[[#This Row],[Inversión real 2018]])/Tabla3[[#This Row],[Inversión real 2018]] -> 0.18976165 | Q38: Construcción | R38: =AVERAGEIF($D$4:$D$103,Q38,$I$4:$I$103) -> 8.5
B39: JUAN | C39: COLOMBIA | D39: Tecnología | E39: Conocimiento | F39: Otro tipo | G39: NO | H39: 5 | I39: 7 | J39: $ - | K39: $ - | L39: $ - | M39: 52936315 | N39: =(Tabla3[[#This Row],[Inversión real 2017]]-Tabla3[[#This Row],[Inversión real 2016]])/Tabla3[[#This Row],[Inversión real 2016]] -> #VALUE! | O39: =(Tabla3[[#This Row],[Inversión real 2017]]-Tabla3[[#This Row],[Inversión real 2018]])/Tabla3[[#This Row],[Inversión real 2018]] -> #VALUE! | Q39: Educación | R39: =AVERAGEIF($D$4:$D$103,Q39,$I$4:$I$103) -> 7.3333333
B40: GONZALO | C40: COLOMBIA | D40: Tecnología | E40: Inversión | F40: Socio capitalista | G40: NO | H40: 9 | I40: 7 | J40: 30000000 | K40: 91413171 | L40: 13211402 | M40: $ - | N40: =(Tabla3[[#This Row],[Inversión real 2017]]-Tabla3[[#This Row],[Inversión real 2016]])/Tabla3[[#This Row],[Inversión real 2016]] -> #VALUE! | O40: =(Tabla3[[#This Row],[Inversión real 2017]]-Tabla3[[#This Row],[Inversión real 2018]])/Tabla3[[#This Row],[Inversión real 2018]] -> -0.85547595
B41: ANTONIO | C41: COLOMBIA | D41: Construcción | E41: Inversión | F41: Socio de proyecto | G41: NO | H41: 4 | I41: 7 | J41: 1000000 | K41: 87347043 | L41: 50796112 | M41: 72757830 | N41: =(Tabla3[[#This Row],[Inversión real 2017]]-Tabla3[[#This Row],[Inversión real 2016]])/Tabla3[[#This Row],[Inversión real 2016]] -> -0.3018468 | O41: =(Tabla3[[#This Row],[Inversión real 2017]]-Tabla3[[#This Row],[Inversión real 2018]])/Tabla3[[#This Row],[Inversión real 2018]] -> -0.41845642
...

Sheet SUMAPRODUCTO
B2: ¿Cuál es la calificación promedio? Teniendo en cuenta que la feria tiene una ponderación del 70% y la de proyectos un 30%. | D2: PONDERACION, TOMAR EN CUENTA EL VALOR QUE TIENE CADA UNO AL MOMENTO DE SACAR ELPROMEDIO | E2: ¿Cuál es la calificación promedio? Teniendo en cuenta que la feria tiene una ponderación del 70% y la de proyectos un 30%.
B3: Tipo | C3: Cantidad | E3: Tipo | F3: Peso porcentual | G3: Cantidad
B4: Feria | C4: 5.8 | E4: Feria | F4: 0.7 | G4: 5.8
B5: Proyectos | C5: 7.6 | D5: PROMEDIO NORMAL | E5: Proyectos | F5: 0.3 | G5: 7.6
B6: Agregado | C6: =(C4*70%)+(C5*30%) -> 6.34 | D6: =AVERAGE(C4:C5) -> 6.7 | E6: Agregado | G6: =SUMPRODUCT(F4:F5,G4:G5) -> 6.34 | H6: SUMAPRODUCTO PARA TENER EL AGREGADO
C7: PROMEDIO AGREGADO
C9: Puntaje del semestre - Clase de Excel
B10: Estudiante | C10: Quiz | D10: Parcial 1 | E10: Parcial final | F10: Puntaje Final
B11: Peso porcentual | C11: 0.2 | D11: 0.3 | E11: 0.5 | G11: recuerda SUMAPRODUCTO ES LA FORMULA
B12: Pedro | C12: 9 | D12: 6 | E12: 5 | F12: =SUMPRODUCT($C$11:$E$11,C12:E12) -> 6.1
B13: Juan | C13: 3 | D13: 4 | E13: 8 | F13: =SUMPRODUCT($C$11:$E$11,C13:E13) -> 5.8
B14: Diego | C14: 4 | D14: 8 | E14: 7 | F14: =SUMPRODUCT($C$11:$E$11,C14:E14) -> 6.7 | H14: ¿Cómo fijar datos adecuadamente?
B15: Felipe | C15: 7 | D15: 8 | E15: 9 | F15: =SUMPRODUCT($C$11:$E$11,C15:E15) -> 8.3
B16: Mateo | C16: 5 | D16: 4 | E16: 7 | F16: =SUMPRODUCT($C$11:$E$11,C16:E16) -> 5.7
B17: Laura | C17: 10 | D17: 9 | E17: 8 | F17: =SUMPRODUCT($C$11:$E$11,C17:E17) -> 8.7
B18: Mónica | C18: 3 | D18: 6 | E18: 6 | F18: =SUMPRODUCT($C$11:$E$11,C18:E18) -> 5.4
B19: Luisa | C19: 4 | D19: 4 | E19: 9 | F19: =SUMPRODUCT($C$11:$E$11,C19:E19) -> 6.5 | G19: Reto | H19: Obtener Puntaje Final de cada estudiante (cada elemento tiene una equivalencia)
B20: Felipe | C20: 4 | D20: 3 | E20: 6 | F20: =SUMPRODUCT($C$11:$E$11,C20:E20) -> 4.7 | G20: (pausa) | H20: R. Cuantos estudiantes tiene la tabla (con fórmula)
B21: Orlando | C21: 5 | D21: 4 | E21: 7 | F21: =SUMPRODUCT($C$11:$E$11,C21:E21) -> 5.7 | H21: R. Cuál es el promedio de los estudiantes (Puntaje Final) | I21: =AVERAGE(F12:F27) -> 6.20625
B22: Marcela | C22: 6 | D22: 5 | E22: 8 | F22: =SUMPRODUCT($C$11:$E$11,C22:E22) -> 6.7
B23: María | C23: 4 | D23: 3 | E23: 6 | F23: =SUMPRODUCT($C$11:$E$11,C23:E23) -> 4.7
B24: César | C24: 5 | D24: 4 | E24: 7 | F24: =SUMPRODUCT($C$11:$E$11,C24:E24) -> 5.7
B25: Catalina | C25: 6 | D25: 5 | E25: 8 | F25: =SUMPRODUCT($C$11:$E$11,C25:E25) -> 6.7
B26: Natalia | C26: 3 | D26: 6 | E26: 6 | F26: =SUMPRODUCT($C$11:$E$11,C26:E26) -> 5.4
B27: Lorena | C27: 4 | D27: 4 | E27: 9 | F27: =SUMPRODUCT($C$11:$E$11,C27:E27) -> 6.5
B29: CONTEO | C29: =COUNTA(B12:B27) -> 16
J30: Fijación de Datos
J31: 1 | K31: 2 | L31: 3
J32: 4 | K32: 5 | L32: 6
J33: 7 | K33: 8 | L33: 9
J35: =SUM(J31:J33) -> 12 | K35: =SUM(K31:K33) -> 15 | L35: =SUM(L31:L33) -> 18 | M35: SIN FIJAR NADA SE VA MOVIENDO LA FILA | O35: =SUM($J31:$J33) -> 12 | P35: =SUM($J31:$J33) -> 12 | Q35: =SUM($J31:$J33) -> 12 | R35: COLUMNAS
J36: =SUM(J32:J34) -> 11 | K36: =SUM(K32:K34) -> 13 | L36: =SUM(L32:L34) -> 15 | O36: =SUM($J32:$J34) -> 11 | P36: =SUM($J32:$J34) -> 11 | Q36: =SUM($J32:$J34) -> 11 | R36: FIJAS
J37: =SUM(J33:J35) -> 19 | K37: =SUM(K33:K35) -> 23 | L37: =SUM(L33:L35) -> 27 | O37: =SUM($J33:$J35) -> 19 | P37: =SUM($J33:$J35) -> 19 | Q37: =SUM($J33:$J35) -> 19 | R37: =SUMA($J31:$J33)
J38: =SUM(J34:J36) -> 23 | K38: =SUM(K34:K36) -> 28 | L38: =SUM(L34:L36) -> 33 | O38: =SUM($J34:$J36) -> 23 | P38: =SUM($J34:$J36) -> 23 | Q38: =SUM($J34:$J36) -> 23
J39: =SUM(J35:J37) -> 42 | K39: =SUM(K35:K37) -> 51 | L39: =SUM(L35:L37) -> 60 | O39: =SUM($J35:$J37) -> 42 | P39: =SUM($J35:$J37) -> 42 | Q39: =SUM($J35:$J37) -> 42
J42: =SUM($J$31:$J$33) -> 12 | K42: =SUM($J$31:$J$33) -> 12 | L42: =SUM($J$31:$J$33) -> 12 | M42: FIJO TODO NO SE MUEVE DE LA MISMA FILA | O42: =SUM(J$31:J$33) -> 12 | P42: =SUM(K$31:K$33) -> 15 | Q42: =SUM(L$31:L$33) -> 18 | R42: FILAS FIJAS
J43: =SUM($J$31:$J$33) -> 12 | K43: =SUM($J$31:$J$33) -> 12 | L43: =SUM($J$31:$J$33) -> 12 | O43: =SUM(J$31:J$33) -> 12 | P43: =SUM(K$31:K$33) -> 15 | Q43: =SUM(L$31:L$33) -> 18
J44: =SUM($J$31:$J$33) -> 12 | K44: =SUM($J$31:$J$33) -> 12 | L44: =SUM($J$31:$J$33) -> 12 | O44: =SUM(J$31:J$33) -> 12 | P44: =SUM(K$31:K$33) -> 15 | Q44: =SUM(L$31:L$33) -> 18
J45: =SUM($J$31:$J$33) -> 12 | K45: =SUM($J$31:$J$33) -> 12 | L45: =SUM($J$31:$J$33) -> 12 | O45: =SUM(J$31:J$33) -> 12 | P45: =SUM(K$31:K$33) -> 15 | Q45: =SUM(L$31:L$33) -> 18
J46: =SUM($J$31:$J$33) -> 12 | K46: =SUM($J$31:$J$33) -> 12 | L46: =SUM($J$31:$J$33) -> 12 | O46: =SUM(J$31:J$33) -> 12 | P46: =SUM(K$31:K$33) -> 15 | Q46: =SUM(L$31:L$33) -> 18
...

Sheet SUMAPRODUCTO2
K2: Primer punto
A3: Nombre | B3: País de orígen | C3: Sector | D3: Intención frente a los proyectos | E3: Detalle inversión | F3: Conoce algún proyecto o no | G3: Calificación Feria (1-10) | H3: Calificación Proyectos (1-10) | I3: Calificación personal | K3: ¿Cuál es la calificación de cada uno, teniendo en cuenta que los proyectos tienen un peso porcentual del 80% y la feria del 20%?
A4: ALBERT | B4: COLOMBIA | C4: Educación | D4: Conocimiento | E4: Académico | F4: NO | G4: 3 | H4: 8 | I4: =AVERAGE($G4:$H4) -> 5.5 | K4: Cuantas personas tiene la tabla (con fórmula) | Q4: =COUNTA(A4:A103) -> 100
A5: JOAQUIN | B5: COLOMBIA | C5: Tecnología | D5: Inversión | E5: Socio capitalista | F5: SI | G5: 8 | H5: 7 | I5: =AVERAGE($G5:$H5) -> 7.5 | K5: Cuál es el promedio de ambas calificaciones? (Puntaje Final)
A6: CESAR | B6: COLOMBIA | C6: Construcción | D6: Trabajo | E6: Ofreciendo trabajo | F6: NO | G6: 5 | H6: 10 | I6: =AVERAGE($G6:$H6) -> 7.5 | K6: PROMEDIOS PONDERADOS | L6: 0.2 | M6: 0.8 | N6: PROMEDIO NORMAL | P6: PROMEDIOS PONDERADOS
A7: HUGO | B7: COLOMBIA | C7: Tecnología | D7: Inversión | E7: Socio de proyecto | F7: NO | G7: 4 | H7: 8 | I7: =AVERAGE($G7:$H7) -> 6 | K7: =SUMPRODUCT(L6:M6,L7:M7) -> 7.21 | L7: =AVERAGE(G4:G103) -> 5.81 | M7: =AVERAGE(H4:H103) -> 7.56 | N7: =AVERAGE(L7:M7) -> 6.685 | P7: PROMEDIOS PONDERADOS
A8: VALENTINA | B8: COLOMBIA | C8: Construcción | D8: Inversión | E8: Socio capitalista | F8: NO | G8: 4 | H8: 9 | I8: =AVERAGE($G8:$H8) -> 6.5
A9: GERMAN | B9: COLOMBIA | C9: Tecnología | D9: Inversión | E9: Socio de proyecto | F9: NO | G9: 9 | H9: 7 | I9: =AVERAGE($G9:$H9) -> 8 | K9: Segundo punto
A10: DAVID | B10: COLOMBIA | C10: Tecnología | D10: Trabajo | E10: Ofreciendo trabajo | F10: NO | G10: 5 | H10: 9 | I10: =AVERAGE($G10:$H10) -> 7 | K10: Crear un hipervínculo que lo lleve a la celda Q100 de esta hoja.
A11: MIGUEL | B11: COLOMBIA | C11: Tecnología | D11: Inversión | E11: Socio capitalista | F11: SI | G11: 8 | H11: 10 | I11: =AVERAGE($G11:$H11) -> 9
A12: VICENTE | B12: COLOMBIA | C12: Agroindustrial | D12: Trabajo | E12: Ofreciendo trabajo | F12: SI | G12: 8 | H12: 3 | I12: =AVERAGE($G12:$H12) -> 5.5
A13: ALVARO | B13: COLOMBIA | C13: Sector Real | D13: Inversión | E13: Socio de proyecto | F13: NO | G13: 5 | H13: 9 | I13: =AVERAGE($G13:$H13) -> 7
A14: LUIS | B14: VENEZUELA | C14: Tecnología | D14: Inversión | E14: Socio de proyecto | F14: NO | G14: 4 | H14: 5 | I14: =AVERAGE($G14:$H14) -> 4.5
A15: DANIEL | B15: COLOMBIA | C15: Tecnología | D15: Inversión | E15: Socio de proyecto | F15: NO | G15: 3 | H15: 8 | I15: =AVERAGE($G15:$H15) -> 5.5
A16: JOSEP | B16: COLOMBIA | C16: Construcción | D16: Trabajo | E16: Buscando trabajo | F16: NO | G16: 7 | H16: 9 | I16: =AVERAGE($G16:$H16) -> 8
A17: EDUARDO | B17: COLOMBIA | C17: Tecnología | D17: Trabajo | E17: Buscando trabajo | F17: SI | G17: 4 | H17: 8 | I17: =AVERAGE($G17:$H17) -> 6
A18: LEONEL | B18: COLOMBIA | C18: Sector Real | D18: Inversión | E18: Socio capitalista | F18: NO | G18: 9 | H18: 10 | I18: =AVERAGE($G18:$H18) -> 9.5
A19: JORDI | B19: COLOMBIA | C19: Educación | D19: Conocimiento | E19: Académico | F19: NO | G19: 4 | H19: 6 | I19: =AVERAGE($G19:$H19) -> 5
A20: ESTEBAN | B20: COLOMBIA | C20: Tecnología | D20: Inversión | E20: Socio capitalista | F20: NO | G20: 5 | H20: 7 | I20: =AVERAGE($G20:$H20) -> 6
A21: JONATHAN | B21: COLOMBIA | C21: Educación | D21: Conocimiento | E21: Académico | F21: NO | G21: 6 | H21: 7 | I21: =AVERAGE($G21:$H21) -> 6.5
A22: FELIPE | B22: BRASIL | C22: Sector Real | D22: Trabajo | E22: Buscando trabajo | F22: SI | G22: 9 | H22: 8 | I22: =AVERAGE($G22:$H22) -> 8.5
... A103: ADRIAN | B103: COLOMBIA | C103: Tecnología | D103: Trabajo | E103: Ofreciendo trabajo | F103: NO | G103: 5 | H103: 10 | I103: =AVERAGE($G103:$H103) -> 7.5
B105: TRANSPONER
A106: Nombre | B106: ALBERT | C106: JOAQUIN | D106: CESAR | E106: HUGO | F106: VALENTINA | G106: GERMAN | H106: DAVID | I106: MIGUEL | J106: VICENTE | K106: ALVARO | L106: LUIS | M106: DANIEL | N106: JOSEP | O106: EDUARDO | P106: LEONEL | Q106: JORDI | R106: ESTEBAN | S106: JONATHAN | T106: FELIPE | U106: JOSE | V106: FELIX | W106: PABLO | X106: MANUEL | Y106: LORENZO | Z106: ISAAC | AA106: MARIA | AB106: ANGEL | AC106: ADOLFO | AD106: ERNESTO | AE106: RAFAEL | AF106: TOMAS | AG106: MARCOS | AH106: MARIO | AI106: ARTURO | AJ106: EUGENIO | AK106: JUAN | AL106: GONZALO | AM106: ANTONIO | AN106: EMILIO | AO106: AGUSTIN | AP106: JUAN PABLO | AQ106: FRANCISCO | AR106: MARC | AS106: ROBERTO | AT106: CARLOS | AU106: JOEL | AV106: MARIANO | AW106: OSCAR | AX106: ALEXANDER | AY106: BORJA | AZ106: RAUL | BA106: ALEX | BB106: IVAN | BC106: SAMUEL | BD106: ANDRES | BE106: NORA | BF106: ANDRÉS | BG106: CRISTIAN | BH106: JAVIER | BI106: DOMINGO | BJ106: NICOLAS | BK106: HECTOR | BL106: RICARDO | BM106: ALBERTO | BN106: RUBEN | BO106: SEBASTIAN | BP106: MOHAMED | BQ106: MARCO | BR106: SERGIO | BS106: RAMON | BT106: GREGORIO | BU106: JOAN | BV106: ALFONSO | BW106: GUILLERMO | BX106: CHRISTIAN | BY106: MATEO | BZ106: JULIAN | CA106: CRISTOBAL | CB106: RODRIGO | CC106: JESUS | CD106: JORGE | CE106: JULIO | CF106: MARIA MÓNICA | CG106: IGNACIO | CH106: GABRIEL | CI106: MARTIN | CJ106: FERNANDO | CK106: ALEJANDRO | CL106: SANTIAGO | CM106: LUCAS | CN106: PEDRO | CO106: ENRIQUE | CP106: VICTOR | CQ106: ALFREDO | CR106: DARIO | CS106: DIEGO | CT106: ISMAEL | CU106: JAIME | CV106: SALVADOR | CW106: ADRIAN
A107: País de orígen | B107: COLOMBIA | C107: COLOMBIA | D107: COLOMBIA | E107: COLOMBIA | F107: COLOMBIA | G107: COLOMBIA | H107: COLOMBIA | I107: COLOMBIA | J107: COLOMBIA | K107: COLOMBIA | L107: VENEZUELA | M107: COLOMBIA | N107: COLOMBIA | O107: COLOMBIA | P107: COLOMBIA | Q107: COLOMBIA | R107: COLOMBIA | S107: COLOMBIA | T107: BRASIL | U107: COLOMBIA | V107: COLOMBIA | W107: COLOMBIA | X107: ARGENTINA | Y107: COLOMBIA | Z107: COLOMBIA | AA107: COLOMBIA | AB107: COLOMBIA | AC107: COLOMBIA | AD107: COLOMBIA | AE107: COLOMBIA | AF107: COLOMBIA | AG107: BRASIL | AH107: COLOMBIA | AI107: COLOMBIA | AJ107: COLOMBIA | AK107: COLOMBIA | AL107: COLOMBIA | AM107: COLOMBIA | AN107: COLOMBIA | AO107: COLOMBIA | AP107: COLOMBIA | AQ107: COLOMBIA | AR107: COLOMBIA | AS107: COLOMBIA | AT107: COLOMBIA | AU107: COLOMBIA | AV107: COLOMBIA | AW107: BRASIL | AX107: COLOMBIA | AY107: ECUADOR | AZ107: BRASIL | BA107: URUGUAY | BB107: COLOMBIA | BC107: COLOMBIA | BD107: COLOMBIA | BE107: CHILE | BF107: COLOMBIA | BG107: COLOMBIA | BH107: BOLIVIA | BI107: COLOMBIA | BJ107: COLOMBIA | BK107: COLOMBIA | BL107: COLOMBIA | BM107: COLOMBIA | BN107: COLOMBIA | BO107: COLOMBIA | BP107: COLOMBIA | BQ107: PERU | BR107: BRASIL | BS107: COLOMBIA | BT107: COLOMBIA | BU107: COLOMBIA | BV107: COLOMBIA | BW107: COLOMBIA | BX107: COLOMBIA | BY107: URUGUAY | BZ107: COLOMBIA | CA107: COLOMBIA | CB107: COLOMBIA | CC107: OTRO PAÍS DEL MUNDO | CD107: CHILE | CE107: COLOMBIA | CF107: COLOMBIA | CG107: COLOMBIA | CH107: COLOMBIA | CI107: COLOMBIA | CJ107: COLOMBIA | CK107: COLOMBIA | CL107: CHILE | CM107: COLOMBIA | CN107: CHILE | CO107: COLOMBIA | CP107: COLOMBIA | CQ107: PARAGUAY | CR107: COLOMBIA | CS107: COLOMBIA | CT107: BRASIL | CU107: COLOMBIA | CV107: COLOMBIA | CW107: COLOMBIA
A108: Sector | B108: Educación | C108: Tecnología | D108: Construcción | E108: Tecnología | F108: Construcción | G108: Tecnología | H108: Tecnología | I108: Tecnología | J108: Agroindustrial | K108: Sector Real | L108: Tecnología | M108: Tecnología | N108: Construcción | O108: Tecnología | P108: Sector Real | Q108: Educación | R108: Tecnología | S108: Educación | T108: Sector Real | U108: Tecnología | V108: Tecnología | W108: Agroindustrial | X108: Sector Real | Y108: Agroindustrial | Z108: Tecnología | AA108: Sector Real | AB108: Tecnología | AC108: Sector Real | AD108: Tecnología | AE108: Sector Real | AF108: Agroindustrial | AG108: Sector Real | AH108: Tecnología | AI108: Sector Real | AJ108: Construcción | AK108: Tecnología | AL108: Tecnología | AM108: Construcción | AN108: Sector Real | AO108: Tecnología | AP108: Tecnología | AQ108: Tecnología | AR108: Sector Real | AS108: Tecnología | AT108: Tecnología | AU108: Sector Real | AV108: Sector Real | AW108: Tecnología | AX108: Construcción | AY108: Tecnología | AZ108: Tecnología | BA108: Tecnología | BB108: Tecnología | BC108: Sector Real | BD108: Tecnología | BE108: Sector Real | BF108: Tecnología | BG108: Tecnología | BH108: Tecnología | BI108: Educación | BJ108: Sector Real | BK108: Tecnología | BL108: Sector Real | BM108: Sector Real | BN108: Tecnología | BO108: Tecnología | BP108: Agroindustrial | BQ108: Tecnología | BR108: Sector Real | BS108: Agroindustrial | BT108: Agroindustrial | BU108: Tecnología | BV108: Tecnología | BW108: Agroindustrial | BX108: Construcción | BY108: Tecnología | BZ108: Tecnología | CA108: Tecnología | CB108: Sector Real | CC108: Educación | CD108: Tecnología | CE108: Sector Real | CF108: Tecnología | CG108: Tecnología | CH108: Tecnología | CI108: Tecnología | CJ108: Tecnología | CK108: Tecnología | CL108: Tecnología | CM108: Construcción | CN108: Educación | CO108: Tecnología | CP108: Tecnología | CQ108: Tecnología | CR108: Tecnología | CS108: Tecnología | CT108: Tecnología | CU108: Tecnología | CV108: Tecnología | CW108: Tecnología
A109: Intención frente a los proyectos | B109: Conocimiento | C109: Inversión | D109: Trabajo | E109: Inversión | F109: Inversión | G109: Inversión | H109: Trabajo | I109: Inversión | J109: Trabajo | K109: Inversión | L109: Inversión | M109: Inversión | N109: Trabajo | O109: Trabajo | P109: Inversión | Q109: Conocimiento | R109: Inversión | S109: Conocimiento | T109: Trabajo | U109: Inversión | V109: Inversión | W109: Inversión | X109: Trabajo | Y109: Inversión | Z109: Inversión | AA109: Inversión | AB109: Trabajo | AC109: Trabajo | AD109: Inversión | AE109: Inversión | AF109: Trabajo | AG109: Trabajo | AH109: Inversión | AI109: Inversión | AJ109: Inversión | AK109: Conocimiento | AL109: Inversión | AM109: Inversión | AN109: Trabajo | AO109: Inversión | AP109: Inversión | AQ109: Inversión | AR109: Inversión | AS109: Inversión | AT109: Inversión | AU109: Inversión | AV109: Trabajo | AW109: Inversión | AX109: Inversión | AY109: Inversión | AZ109: Trabajo | BA109: Inversión | BB109: Inversión | BC109: Inversión | BD109: Trabajo | BE109: Inversión | BF109: Inversión | BG109: Trabajo | BH109: Inversión | BI109: Conocimiento | BJ109: Inversión | BK109: Inversión | BL109: Inversión | BM109: Trabajo | BN109: Inversión | BO109: Inversión | BP109: Trabajo | BQ109: Conocimiento | BR109: Inversión | BS109: Trabajo | BT109: Inversión | BU109: Trabajo | BV109: Inversión | BW109: Inversión | BX109: Trabajo | BY109: Trabajo | BZ109: Inversión | CA109: Trabajo | CB109: Trabajo | CC109: Conocimiento | CD109: Inversión | CE109: Trabajo | CF109: Trabajo | CG109: Trabajo | CH109: Trabajo | CI109: Trabajo | CJ109: Trabajo | CK109: Inversión | CL109: Inversión | CM109: Inversión | CN109: Conocimiento | CO109: Inversión | CP109: Trabajo | CQ109: Trabajo | CR109: Inversión | CS109: Inversión | CT109: Inversión | CU109: Inversión | CV109: Inversión | CW109: Trabajo
A110: Detalle inversión | B110: Académico | C110: Socio capitalista | D110: Ofreciendo trabajo | E110: Socio de proyecto | F110: Socio capitalista | G110: Socio de proyecto | H110: Ofreciendo trabajo | I110: Socio capitalista | J110: Ofreciendo trabajo | K110: Socio de proyecto | L110: Socio de proyecto | M110: Socio de proyecto | N110: Buscando trabajo | O110: Buscando trabajo | P110: Socio capitalista | Q110: Académico | R110: Socio capitalista | S110: Académico | T110: Buscando trabajo | U110: Socio de proyecto | V110: Socio de proyecto | W110: Socio capitalista | X110: Ofreciendo trabajo | Y110: Socio capitalista | Z110: Socio capitalista | AA110: Socio capitalista | AB110: Ofreciendo trabajo | AC110: Ofreciendo trabajo | AD110: Socio de proyecto | AE110: Socio capitalista | AF110: Ofreciendo trabajo | AG110: Buscando trabajo | AH110: Socio capitalista | AI110: Socio de proyecto | AJ110: Socio de proyecto | AK110: Otro tipo | AL110: Socio capitalista | AM110: Socio de proyecto | AN110: Buscando trabajo | AO110: Socio de proyecto | AP110: Socio de proyecto | AQ110: Socio de proyecto | AR110: Socio de proyecto | AS110: Socio de proyecto | AT110: Socio de proyecto | AU110: Socio de proyecto | AV110: Ofreciendo trabajo | AW110: Socio de proyecto | AX110: Socio capitalista | AY110: Socio capitalista | AZ110: Ofreciendo trabajo | BA110: Socio capitalista | BB110: Socio de proyecto | BC110: Socio de proyecto | BD110: Buscando trabajo | BE110: Socio de proyecto | BF110: Socio capitalista | BG110: Buscando trabajo | BH110: Socio capitalista | BI110: Académico | BJ110: Socio capitalista | BK110: Socio de proyecto | BL110: Socio capitalista | BM110: Ofreciendo trabajo | BN110: Socio capitalista | BO110: Socio capitalista | BP110: Buscando trabajo | BQ110: Otro tipo | BR110: Socio de proyecto | BS110: Buscando trabajo | BT110: Socio de proyecto | BU110: Ofreciendo trabajo | BV110: Socio de proyecto | BW110: Socio capitalista | BX110: Ofreciendo trabajo | BY110: Buscando trabajo | BZ110: Socio capitalista | CA110: Buscando trabajo | CB110: Buscando trabajo | CC110: Académico | CD110: Socio capitalista | CE110: Buscando trabajo | CF110: Buscando trabajo | CG110: Buscando trabajo | CH110: Ofreciendo trabajo | CI110: Buscando trabajo | CJ110: Buscando trabajo | CK110: Socio capitalista | CL110: Socio capitalista | CM110: Socio capitalista | CN110: Académico | CO110: Socio capitalista | CP110: Buscando trabajo | CQ110: Buscando trabajo | CR110: Socio de proyecto | CS110: Socio de proyecto | CT110: Socio de proyecto | CU110: Socio capitalista | CV110: Socio de proyecto | CW110: Ofreciendo trabajo
A111: Conoce algún proyecto o no | B111: NO | C111: SI | D111: NO | E111: NO | F111: NO | G111: NO | H111: NO | I111: SI | J111: SI | K111: NO | L111: NO | M111: NO | N111: NO | O111: SI | P111: NO | Q111: NO | R111: NO | S111: NO | T111: SI | U111: NO | V111: NO | W111: SI | X111: NO | Y111: NO | Z111: NO | AA111: NO | AB111: NO | AC111: NO | AD111: NO | AE111: SI | AF111: NO | AG111: SI | AH111: NO | AI111: NO | AJ111: NO | AK111: NO | AL111: NO | AM111: NO | AN111: NO | AO111: NO | AP111: SI | AQ111: SI | AR111: SI | AS111: SI | AT111: NO | AU111: NO | AV111: NO | AW111: SI | AX111: SI | AY111: NO | AZ111: SI | BA111: NO | BB111: NO | BC111: NO | BD111: SI | BE111: NO | BF111: NO | BG111: NO | BH111: NO | BI111: NO | BJ111: NO | BK111: NO | BL111: NO | BM111: NO | BN111: SI | BO111: NO | BP111: NO | BQ111: NO | BR111: SI | BS111: NO | BT111: SI | BU111: NO | BV111: SI | BW111: NO | BX111: NO | BY111: NO | BZ111: SI | CA111: SI | CB111: SI | CC111: NO | CD111: NO | CE111: NO | CF111: NO | CG111: NO | CH111: SI | CI111: SI | CJ111: NO | CK111: SI | CL111: NO | CM111: SI | CN111: NO | CO111: NO | CP111: SI | CQ111: SI | CR111: NO | CS111: NO | CT111: NO | CU111: NO | CV111: NO | CW111: NO
A112: Calificación Feria (1-10) | B112: 3 | C112: 8 | D112: 5 | E112: 4 | F112: 4 | G112: 9 | H112: 5 | I112: 8 | J112: 8 | K112: 5 | L112: 4 | M112: 3 | N112: 7 | O112: 4 | P112: 9 | Q112: 4 | R112: 5 | S112: 6 | T112: 9 | U112: 5 | V112: 6 | W112: 6 | X112: 8 | Y112: 7 | Z112: 9 | AA112: 3 | AB112: 6 | AC112: 9 | AD112: 8 | AE112: 8 | AF112: 6 | AG112: 3 | AH112: 6 | AI112: 6 | AJ112: 8 | AK112: 5 | AL112: 9 | AM112: 4 | AN112: 4 | AO112: 9 | AP112: 6 | AQ112: 8 | AR112: 6 | AS112: 7 | AT112: 5 | AU112: 3 | AV112: 7 | AW112: 5 | AX112: 9 | AY112: 6 | AZ112: 7 | BA112: 5 | BB112: 4 | BC112: 7 | BD112: 3 | BE112: 3 | BF112: 7 | BG112: 5 | BH112: 9 | BI112: 4 | BJ112: 5 | BK112: 3 | BL112: 3 | BM112: 5 | BN112: 7 | BO112: 7 | BP112: 5 | BQ112: 7 | BR112: 8 | BS112: 3 | BT112: 8 | BU112: 5 | BV112: 6 | BW112: 3 | BX112: 8 | BY112: 5 | BZ112: 8 | CA112: 4 | CB112: 9 | CC112: 6 | CD112: 3 | CE112: 3 | CF112: 7 | CG112: 3 | CH112: 7 | CI112: 9 | CJ112: 3 | CK112: 8 | CL112: 7 | CM112: 3 | CN112: 6 | CO112: 8 | CP112: 3 | CQ112: 6 | CR112: 7 | CS112: 6 | CT112: 3 | CU112: 4 | CV112: 4 | CW112: 5
